{
 "cells": [
  {
   "cell_type": "code",
   "execution_count": null,
   "metadata": {},
   "outputs": [],
   "source": [
    "###Module 5: Unit testing"
   ]
  },
  {
   "cell_type": "code",
   "execution_count": null,
   "metadata": {},
   "outputs": [],
   "source": [
    "import unittest\n",
    "\n",
    "\n",
    "class TestSum(unittest.TestCase):\n",
    "\n",
    "    def test_sum(self):\n",
    "        self.assertEqual(sum([1, 2, 3]), 6, \"Should be 6\")\n",
    "\n",
    "    def test_sum_tuple(self):\n",
    "        self.assertEqual(sum((1, 2, 2)), 6, \"Should be 6\")\n",
    "\n",
    "if __name__ == '__main__':\n",
    "    unittest.main()\n",
    "\n",
    "\n",
    "\"\"\"\n",
    "\n",
    " python -u \"/Users/maiwasetembo/Desktop/Ivy Tech/Software Dev using Python/Module05/module05python/practice_unittest.py\"\n",
    ".F\n",
    "======================================================================\n",
    "FAIL: test_sum_tuple (__main__.TestSum.test_sum_tuple)\n",
    "----------------------------------------------------------------------\n",
    "Traceback (most recent call last):\n",
    "  File \"/Users/maiwasetembo/Desktop/Ivy Tech/Software Dev using Python/Module05/module05python/practice_unittest.py\", line 10, in test_sum_tuple\n",
    "    self.assertEqual(sum((1, 2, 2)), 6, \"Should be 6\")\n",
    "AssertionError: 5 != 6 : Should be 6\n",
    "\n",
    "----------------------------------------------------------------------\n",
    "Ran 2 tests in 0.000s\n",
    "\n",
    "FAILED (failures=1)\n",
    "\n",
    "[Done] exited with code=1 in 0.052 seconds\n",
    "\n",
    "\"\"\"\n",
    "\n",
    "###Explanation:\n",
    "# When an assertion fails in Python's unittest framework, it raises an AssertionError and provides details about the mismatch, helping to identify the issue. Debugging involves using the traceback and analyzing the test logic to pinpoint why the test failed and making necessary corrections. Test result symbols include a dot (.) for a successfully passed test and an F for a failed test, with a summary at the end indicating the total number of tests run and the number of failures.\n",
    "\n"
   ]
  },
  {
   "cell_type": "code",
   "execution_count": null,
   "metadata": {},
   "outputs": [],
   "source": [
    "import unittest\n",
    "\n",
    "from my_sum import sum\n",
    "from fractions import Fraction\n",
    "\n",
    "class TestSum(unittest.TestCase):\n",
    "    def test_list_int(self):\n",
    "        \"\"\"\n",
    "        Test that it can sum a list of integers\n",
    "        \"\"\"\n",
    "        data = [1, 2, 3]\n",
    "        result = sum(data)\n",
    "        self.assertEqual(result, 6)\n",
    "\n",
    "    def test_list_fraction(self):\n",
    "        \"\"\"\n",
    "        Test that it can sum a list of fractions\n",
    "        \"\"\"\n",
    "        data = [Fraction(1, 4), Fraction(1, 4), Fraction(2, 5)]\n",
    "        result = sum(data)\n",
    "        self.assertEqual(result, 1)\n",
    "if __name__ == '__main__':\n",
    "    unittest.main()\n",
    "\n",
    "\n",
    "\"\"\"\n",
    "[Running] python -u \"/Users/maiwasetembo/Desktop/Ivy Tech/Software Dev using Python/Module05/module05python/test.py\"\n",
    "F.\n",
    "======================================================================\n",
    "FAIL: test_list_fraction (__main__.TestSum.test_list_fraction)\n",
    "Test that it can sum a list of fractions\n",
    "----------------------------------------------------------------------\n",
    "Traceback (most recent call last):\n",
    "  File \"/Users/maiwasetembo/Desktop/Ivy Tech/Software Dev using Python/Module05/module05python/test.py\", line 21, in test_list_fraction\n",
    "    self.assertEqual(result, 1)\n",
    "AssertionError: Fraction(9, 10) != 1\n",
    "\n",
    "----------------------------------------------------------------------\n",
    "Ran 2 tests in 0.000s\n",
    "\n",
    "FAILED (failures=1)\n",
    "\n",
    "[Done] exited with code=1 in 0.087 seconds\n",
    "\n",
    "\n",
    "\"\"\"\n",
    "\n",
    "###Explanation\n",
    "\n",
    "#The output shows that two tests were executed, one of which failed, as indicated by the F. in the results. The failure occurred in the test_list_fraction function, part of the TestSum test case. This test checks if the function can correctly sum a list of fractions and asserts that the result should equal 1. However, the test failed because the actual result was Fraction(9, 10), which does not match the expected value of 1. The AssertionError provides a clear comparison of the expected and actual results, helping to identify the issue. The traceback points to line 21 in the test.py file, where the failing assertion was made, aiding in debugging. The summary indicates that two tests were run in a very short time (0.000s), and one test failed. The developer can use this information to analyze why the summing function did not return the expected result and adjust the code or test as necessary."
   ]
  },
  {
   "cell_type": "code",
   "execution_count": null,
   "metadata": {},
   "outputs": [],
   "source": []
  }
 ],
 "metadata": {
  "language_info": {
   "name": "python"
  }
 },
 "nbformat": 4,
 "nbformat_minor": 2
}
